============================= test session starts ==============================
platform linux -- Python 3.12.3, pytest-8.4.1, pluggy-1.6.0 -- /workspaces/triune-ai-consciousness/.venv/bin/python
cachedir: .pytest_cache
rootdir: /workspaces/triune-ai-consciousness
configfile: pytest.ini
plugins: anyio-4.9.0, asyncio-1.0.0, cov-6.2.1
asyncio: mode=Mode.AUTO, asyncio_default_fixture_loop_scope=None, asyncio_default_test_loop_scope=function
collecting ... collected 0 items

=============================== warnings summary ===============================
.venv/lib/python3.12/site-packages/_pytest/config/__init__.py:1474
  /workspaces/triune-ai-consciousness/.venv/lib/python3.12/site-packages/_pytest/config/__init__.py:1474: PytestConfigWarning: Unknown config option: plugins
  
    self._warn_or_fail_if_strict(f"Unknown config option: {key}\n")

.venv/lib/python3.12/site-packages/_pytest/config/__init__.py:1474
  /workspaces/triune-ai-consciousness/.venv/lib/python3.12/site-packages/_pytest/config/__init__.py:1474: PytestConfigWarning: Unknown config option: python_paths
  
    self._warn_or_fail_if_strict(f"Unknown config option: {key}\n")

-- Docs: https://docs.pytest.org/en/stable/how-to/capture-warnings.html
============================= 2 warnings in 0.02s ==============================
